Workbook

Sheet Raw Data
A1: Store Location | B1: Region | C1: Product Category | D1: Month | E1: Units Sold | F1: Revenue | G1: Cost | H1: Profit | I1: Customer Satisfaction Score | J1: Employee Count
A2: Newark RM-01 | B2: Northeast | C2: Electronics | D2: 45658 | E2: 94 | F2: 13249.27 | G2: 9657.98 | H2: 3591.29 | I2: 3.91 | J2: 22
A3: Newark RM-01 | B3: Northeast | C3: Home Goods | D3: 45658 | E3: 68 | F3: 5051.64 | G3: 3176.98 | H3: 1874.65 | I3: 4.13 | J3: 22
A4: Newark RM-01 | B4: Northeast | C4: Apparel | D4: 45658 | E4: 104 | F4: 5150.55 | G4: 2968.61 | H4: 2181.94 | I4: 4.12 | J4: 22
A5: Newark RM-01 | B5: Northeast | C5: Beauty | D5: 45658 | E5: 77 | F5: 2783.75 | G5: 1262.46 | H5: 1521.29 | I5: 3.88 | J5: 22
A6: Newark RM-01 | B6: Northeast | C6: Grocery | D6: 45658 | E6: 127 | F6: 2335.93 | G6: 2104.69 | H6: 231.25 | I6: 3.91 | J6: 22
A7: Newark RM-01 | B7: Northeast | C7: Sports | D7: 45658 | E7: 60 | F7: 3611.02 | G7: 2305.67 | H7: 1305.35 | I7: 3.98 | J7: 22
A8: Newark RM-01 | B8: Northeast | C8: Electronics | D8: 45689 | E8: 86 | F8: 11988.63 | G8: 8878.5 | H8: 3110.13 | I8: 4.04 | J8: 21
A9: Newark RM-01 | B9: Northeast | C9: Home Goods | D9: 45689 | E9: 64 | F9: 4978.29 | G9: 3193.74 | H9: 1784.55 | I9: 4.01 | J9: 21
A10: Newark RM-01 | B10: Northeast | C10: Apparel | D10: 45689 | E10: 92 | F10: 4493.07 | G10: 2702.83 | H10: 1790.24 | I10: 4.04 | J10: 21
A11: Newark RM-01 | B11: Northeast | C11: Beauty | D11: 45689 | E11: 83 | F11: 2856.64 | G11: 1361.93 | H11: 1494.71 | I11: 4.06 | J11: 21
A12: Newark RM-01 | B12: Northeast | C12: Grocery | D12: 45689 | E12: 136 | F12: 2401.71 | G12: 2084.27 | H12: 317.44 | I12: 3.76 | J12: 21
A13: Newark RM-01 | B13: Northeast | C13: Sports | D13: 45689 | E13: 56 | F13: 3614.67 | G13: 2292.61 | H13: 1322.06 | I13: 4.14 | J13: 21
... A1801: New Orleans RM-25 | B1801: Southeast | C1801: Sports | D1801: 45992 | E1801: 108 | F1801: 6774.82 | G1801: 5098.8 | H1801: 1676.01 | I1801: 3.45 | J1801: 26

Sheet Data Cleaning
A1: Store Location | B1: Region | C1: Product Category | D1: Month | E1: Month Name | F1: Units Sold | G1: Revenue | H1: Cost | I1: Profit | J1: Profit Margin % | K1: Customer Satisfaction Score | L1: Employee Count | M1: Unique Store-Month Employee Count | N1: Sales per Employee | O1: Data Quality Flag
A2: ='Raw Data'!A2 -> Newark RM-01 | B2: ='Raw Data'!B2 -> Northeast | C2: ='Raw Data'!C2 -> Electronics | D2: ='Raw Data'!D2 -> 45658 | E2: =TEXT(D2,"mmm") -> Jan | F2: ='Raw Data'!E2 -> 94 | G2: ='Raw Data'!F2 -> 13249.27 | H2: ='Raw Data'!G2 -> 9657.98 | I2: =G2-H2 -> 3591.29 | J2: =IFERROR(I2/G2,0) -> 0.27105569 | K2: ='Raw Data'!I2 -> 3.91 | L2: ='Raw Data'!J2 -> 22 | M2: =IF(COUNTIFS($A$2:A2,A2,$D$2:D2,D2)=1,L2,0) -> 22 | N2: =IFERROR(G2/L2,0) -> 602.23955 | O2: =IF(OR(A2="",B2="",C2="",F2<0,G2<0,H2<0,K2<1,K2>5),"Review","OK") -> OK
A3: ='Raw Data'!A3 -> Newark RM-01 | B3: ='Raw Data'!B3 -> Northeast | C3: ='Raw Data'!C3 -> Home Goods | D3: ='Raw Data'!D3 -> 45658 | E3: =TEXT(D3,"mmm") -> Jan | F3: ='Raw Data'!E3 -> 68 | G3: ='Raw Data'!F3 -> 5051.64 | H3: ='Raw Data'!G3 -> 3176.98 | I3: =G3-H3 -> 1874.66 | J3: =IFERROR(I3/G3,0) -> 0.37109929 | K3: ='Raw Data'!I3 -> 4.13 | L3: ='Raw Data'!J3 -> 22 | M3: =IF(COUNTIFS($A$2:A3,A3,$D$2:D3,D3)=1,L3,0) -> 0 | N3: =IFERROR(G3/L3,0) -> 229.62 | O3: =IF(OR(A3="",B3="",C3="",F3<0,G3<0,H3<0,K3<1,K3>5),"Review","OK") -> OK
A4: ='Raw Data'!A4 -> Newark RM-01 | B4: ='Raw Data'!B4 -> Northeast | C4: ='Raw Data'!C4 -> Apparel | D4: ='Raw Data'!D4 -> 45658 | E4: =TEXT(D4,"mmm") -> Jan | F4: ='Raw Data'!E4 -> 104 | G4: ='Raw Data'!F4 -> 5150.55 | H4: ='Raw Data'!G4 -> 2968.61 | I4: =G4-H4 -> 2181.94 | J4: =IFERROR(I4/G4,0) -> 0.42363243 | K4: ='Raw Data'!I4 -> 4.12 | L4: ='Raw Data'!J4 -> 22 | M4: =IF(COUNTIFS($A$2:A4,A4,$D$2:D4,D4)=1,L4,0) -> 0 | N4: =IFERROR(G4/L4,0) -> 234.11591 | O4: =IF(OR(A4="",B4="",C4="",F4<0,G4<0,H4<0,K4<1,K4>5),"Review","OK") -> OK
A5: ='Raw Data'!A5 -> Newark RM-01 | B5: ='Raw Data'!B5 -> Northeast | C5: ='Raw Data'!C5 -> Beauty | D5: ='Raw Data'!D5 -> 45658 | E5: =TEXT(D5,"mmm") -> Jan | F5: ='Raw Data'!E5 -> 77 | G5: ='Raw Data'!F5 -> 2783.75 | H5: ='Raw Data'!G5 -> 1262.46 | I5: =G5-H5 -> 1521.29 | J5: =IFERROR(I5/G5,0) -> 0.54648945 | K5: ='Raw Data'!I5 -> 3.88 | L5: ='Raw Data'!J5 -> 22 | M5: =IF(COUNTIFS($A$2:A5,A5,$D$2:D5,D5)=1,L5,0) -> 0 | N5: =IFERROR(G5/L5,0) -> 126.53409 | O5: =IF(OR(A5="",B5="",C5="",F5<0,G5<0,H5<0,K5<1,K5>5),"Review","OK") -> OK
A6: ='Raw Data'!A6 -> Newark RM-01 | B6: ='Raw Data'!B6 -> Northeast | C6: ='Raw Data'!C6 -> Grocery | D6: ='Raw Data'!D6 -> 45658 | E6: =TEXT(D6,"mmm") -> Jan | F6: ='Raw Data'!E6 -> 127 | G6: ='Raw Data'!F6 -> 2335.93 | H6: ='Raw Data'!G6 -> 2104.69 | I6: =G6-H6 -> 231.24 | J6: =IFERROR(I6/G6,0) -> 0.098992692 | K6: ='Raw Data'!I6 -> 3.91 | L6: ='Raw Data'!J6 -> 22 | M6: =IF(COUNTIFS($A$2:A6,A6,$D$2:D6,D6)=1,L6,0) -> 0 | N6: =IFERROR(G6/L6,0) -> 106.17864 | O6: =IF(OR(A6="",B6="",C6="",F6<0,G6<0,H6<0,K6<1,K6>5),"Review","OK") -> OK
A7: ='Raw Data'!A7 -> Newark RM-01 | B7: ='Raw Data'!B7 -> Northeast | C7: ='Raw Data'!C7 -> Sports | D7: ='Raw Data'!D7 -> 45658 | E7: =TEXT(D7,"mmm") -> Jan | F7: ='Raw Data'!E7 -> 60 | G7: ='Raw Data'!F7 -> 3611.02 | H7: ='Raw Data'!G7 -> 2305.67 | I7: =G7-H7 -> 1305.35 | J7: =IFERROR(I7/G7,0) -> 0.36149066 | K7: ='Raw Data'!I7 -> 3.98 | L7: ='Raw Data'!J7 -> 22 | M7: =IF(COUNTIFS($A$2:A7,A7,$D$2:D7,D7)=1,L7,0) -> 0 | N7: =IFERROR(G7/L7,0) -> 164.13727 | O7: =IF(OR(A7="",B7="",C7="",F7<0,G7<0,H7<0,K7<1,K7>5),"Review","OK") -> OK
A8: ='Raw Data'!A8 -> Newark RM-01 | B8: ='Raw Data'!B8 -> Northeast | C8: ='Raw Data'!C8 -> Electronics | D8: ='Raw Data'!D8 -> 45689 | E8: =TEXT(D8,"mmm") -> Feb | F8: ='Raw Data'!E8 -> 86 | G8: ='Raw Data'!F8 -> 11988.63 | H8: ='Raw Data'!G8 -> 8878.5 | I8: =G8-H8 -> 3110.13 | J8: =IFERROR(I8/G8,0) -> 0.2594233 | K8: ='Raw Data'!I8 -> 4.04 | L8: ='Raw Data'!J8 -> 21 | M8: =IF(COUNTIFS($A$2:A8,A8,$D$2:D8,D8)=1,L8,0) -> 21 | N8: =IFERROR(G8/L8,0) -> 570.88714 | O8: =IF(OR(A8="",B8="",C8="",F8<0,G8<0,H8<0,K8<1,K8>5),"Review","OK") -> OK
A9: ='Raw Data'!A9 -> Newark RM-01 | B9: ='Raw Data'!B9 -> Northeast | C9: ='Raw Data'!C9 -> Home Goods | D9: ='Raw Data'!D9 -> 45689 | E9: =TEXT(D9,"mmm") -> Feb | F9: ='Raw Data'!E9 -> 64 | G9: ='Raw Data'!F9 -> 4978.29 | H9: ='Raw Data'!G9 -> 3193.74 | I9: =G9-H9 -> 1784.55 | J9: =IFERROR(I9/G9,0) -> 0.35846646 | K9: ='Raw Data'!I9 -> 4.01 | L9: ='Raw Data'!J9 -> 21 | M9: =IF(COUNTIFS($A$2:A9,A9,$D$2:D9,D9)=1,L9,0) -> 0 | N9: =IFERROR(G9/L9,0) -> 237.06143 | O9: =IF(OR(A9="",B9="",C9="",F9<0,G9<0,H9<0,K9<1,K9>5),"Review","OK") -> OK
A10: ='Raw Data'!A10 -> Newark RM-01 | B10: ='Raw Data'!B10 -> Northeast | C10: ='Raw Data'!C10 -> Apparel | D10: ='Raw Data'!D10 -> 45689 | E10: =TEXT(D10,"mmm") -> Feb | F10: ='Raw Data'!E10 -> 92 | G10: ='Raw Data'!F10 -> 4493.07 | H10: ='Raw Data'!G10 -> 2702.83 | I10: =G10-H10 -> 1790.24 | J10: =IFERROR(I10/G10,0) -> 0.39844472 | K10: ='Raw Data'!I10 -> 4.04 | L10: ='Raw Data'!J10 -> 21 | M10: =IF(COUNTIFS($A$2:A10,A10,$D$2:D10,D10)=1,L10,0) -> 0 | N10: =IFERROR(G10/L10,0) -> 213.95571 | O10: =IF(OR(A10="",B10="",C10="",F10<0,G10<0,H10<0,K10<1,K10>5),"Review","OK") -> OK
A11: ='Raw Data'!A11 -> Newark RM-01 | B11: ='Raw Data'!B11 -> Northeast | C11: ='Raw Data'!C11 -> Beauty | D11: ='Raw Data'!D11 -> 45689 | E11: =TEXT(D11,"mmm") -> Feb | F11: ='Raw Data'!E11 -> 83 | G11: ='Raw Data'!F11 -> 2856.64 | H11: ='Raw Data'!G11 -> 1361.93 | I11: =G11-H11 -> 1494.71 | J11: =IFERROR(I11/G11,0) -> 0.52324059 | K11: ='Raw Data'!I11 -> 4.06 | L11: ='Raw Data'!J11 -> 21 | M11: =IF(COUNTIFS($A$2:A11,A11,$D$2:D11,D11)=1,L11,0) -> 0 | N11: =IFERROR(G11/L11,0) -> 136.03048 | O11: =IF(OR(A11="",B11="",C11="",F11<0,G11<0,H11<0,K11<1,K11>5),"Review","OK") -> OK
A12: ='Raw Data'!A12 -> Newark RM-01 | B12: ='Raw Data'!B12 -> Northeast | C12: ='Raw Data'!C12 -> Grocery | D12: ='Raw Data'!D12 -> 45689 | E12: =TEXT(D12,"mmm") -> Feb | F12: ='Raw Data'!E12 -> 136 | G12: ='Raw Data'!F12 -> 2401.71 | H12: ='Raw Data'!G12 -> 2084.27 | I12: =G12-H12 -> 317.44 | J12: =IFERROR(I12/G12,0) -> 0.13217249 | K12: ='Raw Data'!I12 -> 3.76 | L12: ='Raw Data'!J12 -> 21 | M12: =IF(COUNTIFS($A$2:A12,A12,$D$2:D12,D12)=1,L12,0) -> 0 | N12: =IFERROR(G12/L12,0) -> 114.36714 | O12: =IF(OR(A12="",B12="",C12="",F12<0,G12<0,H12<0,K12<1,K12>5),"Review","OK") -> OK
A13: ='Raw Data'!A13 -> Newark RM-01 | B13: ='Raw Data'!B13 -> Northeast | C13: ='Raw Data'!C13 -> Sports | D13: ='Raw Data'!D13 -> 45689 | E13: =TEXT(D13,"mmm") -> Feb | F13: ='Raw Data'!E13 -> 56 | G13: ='Raw Data'!F13 -> 3614.67 | H13: ='Raw Data'!G13 -> 2292.61 | I13: =G13-H13 -> 1322.06 | J13: =IFERROR(I13/G13,0) -> 0.36574846 | K13: ='Raw Data'!I13 -> 4.14 | L13: ='Raw Data'!J13 -> 21 | M13: =IF(COUNTIFS($A$2:A13,A13,$D$2:D13,D13)=1,L13,0) -> 0 | N13: =IFERROR(G13/L13,0) -> 172.12714 | O13: =IF(OR(A13="",B13="",C13="",F13<0,G13<0,H13<0,K13<1,K13>5),"Review","OK") -> OK
... A1801: ='Raw Data'!A1801 -> New Orleans RM-25 | B1801: ='Raw Data'!B1801 -> Southeast | C1801: ='Raw Data'!C1801 -> Sports | D1801: ='Raw Data'!D1801 -> 45992 | E1801: =TEXT(D1801,"mmm") -> Dec | F1801: ='Raw Data'!E1801 -> 108 | G1801: ='Raw Data'!F1801 -> 6774.82 | H1801: ='Raw Data'!G1801 -> 5098.8 | I1801: =G1801-H1801 -> 1676.02 | J1801: =IFERROR(I1801/G1801,0) -> 0.2473896 | K1801: ='Raw Data'!I1801 -> 3.45 | L1801: ='Raw Data'!J1801 -> 26 | M1801: =IF(COUNTIFS($A$2:A1801,A1801,$D$2:D1801,D1801)=1,L1801,0) -> 0 | N1801: =IFERROR(G1801/L1801,0) -> 260.57 | O1801: =IF(OR(A1801="",B1801="",C1801="",F1801<0,G1801<0,H1801<0,K1801<1,K1801>5),"Review","OK") -> OK

Sheet Pivot Tables
A1: RetailMax Pivot Tables / Summary Data
A3: Revenue by Store | H3: Profit by Store
A4: Store Location | B4: Revenue | C4: Profit | D4: Margin % | E4: Avg Satisfaction | H4: Store Location | I4: Profit | J4: Revenue | K4: Margin % | L4: Avg Satisfaction
A5: Seattle RM-16 | B5: 730856.29 | C5: 209473.03 | D5: 0.28661316 | E5: 4.6379167 | H5: Seattle RM-16 | I5: 209473.03 | J5: 730856.29 | K5: 0.28661316 | L5: 4.6379167
A6: Austin RM-07 | B6: 697607.46 | C6: 201632.87 | D6: 0.28903485 | E6: 4.5463889 | H6: Austin RM-07 | I6: 201632.87 | J6: 697607.46 | K6: 0.28903485 | L6: 4.5463889
A7: Phoenix RM-18 | B7: 682360.67 | C7: 195450.75 | D7: 0.2864332 | E7: 3.8768056 | H7: Phoenix RM-18 | I7: 195450.75 | J7: 682360.67 | K7: 0.2864332 | L7: 3.8768056
A8: Las Vegas RM-20 | B8: 665469.38 | C8: 193706.37 | D8: 0.29108232 | E8: 3.9325 | H8: Las Vegas RM-20 | I8: 193706.37 | J8: 665469.38 | K8: 0.29108232 | L8: 3.9325
A9: Miami RM-21 | B9: 659892.62 | C9: 189313.8 | D9: 0.28688577 | E9: 4.1211111 | H9: Miami RM-21 | I9: 189313.8 | J9: 659892.62 | K9: 0.28688577 | L9: 4.1211111
A10: Orlando RM-22 | B10: 618435.09 | C10: 177446.9 | D10: 0.2869289 | E10: 3.9961111 | H10: Houston RM-08 | I10: 177964.78 | J10: 614910 | K10: 0.28941598 | L10: 4.0930556
A11: Houston RM-08 | B11: 614910 | C11: 177964.78 | D11: 0.28941598 | E11: 4.0930556 | H11: Orlando RM-22 | I11: 177446.9 | J11: 618435.09 | K11: 0.2869289 | L11: 3.9961111
A12: Nashville RM-24 | B12: 581938.03 | C12: 165426.86 | D12: 0.28426886 | E12: 4.1840278 | H12: Nashville RM-24 | I12: 165426.86 | J12: 581938.03 | K12: 0.28426886 | L12: 4.1840278
A13: Columbus RM-14 | B13: 564845.83 | C13: 161638.54 | D13: 0.286164 | E13: 3.9016667 | H13: Columbus RM-14 | I13: 161638.54 | J13: 564845.83 | K13: 0.286164 | L13: 3.9016667
A14: Philadelphia RM-03 | B14: 557889.11 | C14: 158352.83 | D14: 0.28384284 | E14: 3.5522222 | H14: Indianapolis RM-15 | I14: 159288.41 | J14: 556007.61 | K14: 0.28648602 | L14: 4.06
A15: Indianapolis RM-15 | B15: 556007.61 | C15: 159288.41 | D15: 0.28648602 | E15: 4.06 | H15: Philadelphia RM-03 | I15: 158352.83 | J15: 557889.11 | K15: 0.28384284 | L15: 3.5522222
A16: Denver RM-19 | B16: 548467.75 | C16: 156603.64 | D16: 0.28552935 | E16: 3.8070833 | H16: Denver RM-19 | I16: 156603.64 | J16: 548467.75 | K16: 0.28552935 | L16: 3.8070833
... A29: Detroit RM-12 | B29: 394660.67 | C29: 99151.78 | D29: 0.25123299 | E29: 3.2506944 | H29: Detroit RM-12 | I29: 99151.78 | J29: 394660.67 | K29: 0.25123299 | L29: 3.2506944
A32: Product Category Performance | I32: Monthly Revenue Trend
A33: Product Category | B33: Revenue | C33: Profit | D33: Margin % | E33: Avg Satisfaction | F33: Units Sold | I33: Month | J33: Revenue | K33: Profit | L33: Margin %
A34: Electronics | B34: 5464882.3 | C34: 1124161.6 | D34: 0.20570646 | E34: 3.8435333 | F34: 37497 | I34: 45658 | J34: 844872.6 | K34: 274303.56 | L34: 0.32466855
A35: Apparel | B35: 2085075.1 | C35: 788430.41 | D35: 0.37813046 | E35: 3.8567333 | F35: 42817 | I35: 45689 | J35: 826792.02 | K35: 262501.18 | L35: 0.31749361
A36: Home Goods | B36: 2410593.5 | C36: 767715.33 | D36: 0.31847565 | E36: 3.8589 | F36: 31412 | I36: 45717 | J36: 972561.45 | K36: 304576.22 | L36: 0.31316913
A37: Beauty | B37: 1213124.8 | C37: 604999.69 | D37: 0.49871184 | E37: 3.8567 | F37: 33341 | I37: 45748 | J37: 1029893.5 | K37: 317554.5 | L37: 0.30833723
A38: Sports | B38: 1707050 | C38: 579316.91 | D38: 0.33936728 | E38: 3.8514 | F38: 27236 | I38: 45778 | J38: 1122932.6 | K38: 339666.86 | L38: 0.30248195
A39: Grocery | B39: 1006466.1 | C39: 78428.18 | D39: 0.077924317 | E39: 3.8234 | F39: 55271 | I39: 45809 | J39: 1159230.2 | K39: 342989.81 | L39: 0.29587723
I40: 45839 | J40: 1199263.1 | K40: 347357.88 | L40: 0.28964277
I41: 45870 | J41: 1186344.8 | K41: 341106.48 | L41: 0.28752727
I42: 45901 | J42: 1076452.9 | K42: 297269 | L42: 0.27615607
I43: 45931 | J43: 1134717.7 | K43: 308171.38 | L43: 0.27158418
I44: 45962 | J44: 1570487.9 | K44: 403143 | L44: 0.25669922
I45: 45992 | J45: 1763643 | K45: 404412.21 | L45: 0.22930503
A48: Revenue by Region | I48: Customer Satisfaction by Store
A49: Region | B49: Revenue | C49: Profit | D49: Margin % | E49: Avg Satisfaction | F49: Sales per Employee | I49: Store Location | J49: Avg Satisfaction | K49: Revenue | L49: Profit
A50: West | B50: 3166672 | C50: 910724.18 | D50: 0.28759663 | E50: 4.0496667 | F50: 1819.9264 | I50: Detroit RM-12 | J50: 3.2506944 | K50: 394660.67 | L50: 99151.78
A51: South | B51: 2905456.5 | C51: 837581.21 | D51: 0.2882787 | E51: 3.9819444 | F51: 1775.9514 | I51: Buffalo RM-04 | J51: 3.3522222 | K51: 416811.28 | L51: 106330.87
A52: Southeast | B52: 2883546.3 | C52: 807124.73 | D52: 0.27990698 | E52: 3.9016389 | F52: 1785.4776 | I52: Providence RM-05 | J52: 3.4172222 | K52: 474467.25 | L52: 136379.74
A53: Midwest | B53: 2475171.6 | C53: 695376.1 | D53: 0.28094056 | E53: 3.6733889 | F53: 1836.1807 | I53: Philadelphia RM-03 | J53: 3.5522222 | K53: 557889.11 | L53: 158352.83
A54: Northeast | B54: 2456345.3 | C54: 692245.86 | D54: 0.28181944 | E54: 3.6355833 | F54: 1866.5238 | I54: Cleveland RM-13 | J54: 3.5529167 | K54: 519126.7 | L54: 148655.94
I55: New Orleans RM-25 | J55: 3.5691667 | K55: 494015.54 | L55: 124827.69
I56: Chicago RM-11 | J56: 3.6016667 | K56: 440530.81 | L56: 126641.43
I57: Tampa RM-23 | J57: 3.6377778 | K57: 529265.02 | L57: 150109.48
...

Sheet Calculations
A1: RetailMax KPI Calculations
A3: KPI Category | B3: KPI | C3: Formula / Method | D3: Value
A4: Financial | B4: Total Revenue | C4: SUM of cleaned Revenue | D4: =SUM('Data Cleaning'!G:G) -> 13887192
A5: Financial | B5: Total Profit | C5: SUM of cleaned Profit | D5: =SUM('Data Cleaning'!I:I) -> 3943052.1
A6: Financial | B6: Profit Margin % | C6: Total Profit divided by Total Revenue | D6: =IFERROR(D5/D4,0) -> 0.28393445
A7: Financial | B7: Revenue Growth % | C7: December Revenue minus January Revenue, divided by January Revenue | D7: =IFERROR((SUMIFS('Data Cleaning'!G:G,'Data Cleaning'!D:D,DATE(2025,12,1))-SUMIFS('Data Cleaning'!G:G,'Data Cleaning'!D:D,DATE(2025,1,1)))/SUMIFS('Data Cleaning'!G:G,'Data Cleaning'!D:D,DATE(2025,1,1)),0) -> 1.0874662
A8: Operational | B8: Average Units Sold | C8: AVERAGE of cleaned Units Sold | D8: =AVERAGE('Data Cleaning'!F:F) -> 126.43
A9: Operational | B9: Sales per Employee | C9: Total Revenue divided by unique store-month employee count | D9: =IFERROR(D4/SUM('Data Cleaning'!M:M),0) -> 1814.1335
A10: Customer | B10: Average Customer Satisfaction | C10: AVERAGE of Customer Satisfaction Score | D10: =AVERAGE('Data Cleaning'!K:K) -> 3.8484444
A11: Customer | B11: Highest Satisfaction Location | C11: Highest average satisfaction location from store-level pivot | D11: Seattle RM-16 (4.64)
A12: Customer | B12: Lowest Satisfaction Location | C12: Lowest average satisfaction location from store-level pivot | D12: Detroit RM-12 (3.25)

Sheet Dashboard
A1: RetailMax Profitability Dashboard | P1: Region | Q1: Revenue | S1: Product Category | T1: Profit | V1: Month | W1: Revenue | Y1: Store Location | Z1: Avg Satisfaction
P2: West | Q2: 3166672 | S2: Electronics | T2: 1124161.6 | V2: 45658 | W2: 844872.6 | Y2: Detroit RM-12 | Z2: 3.2506944
A3: KPI | B3: Value | C3: KPI | D3: Value | F3: Key Findings | G3: • Revenue grew 108.7% from January to December, driven by holiday demand and stronger West/South store performance. • Profit margin fell from 32.5% in January to 22.9% in December, showing cost inflation and promotional pressure. • Grocery has the weakest margin (7.8%); Beauty has the highest margin (49.9%). • Detroit RM-12 and Buffalo RM-04 have the lowest satisfaction scores and need service/process improvement. | P3: South | Q3: 2905456.5 | S3: Apparel | T3: 788430.41 | V3: 45689 | W3: 826792.02 | Y3: Buffalo RM-04 | Z3: 3.3522222
A4: Revenue | B4: 13887192 | C4: Revenue Growth % | D4: 1.0874662 | P4: Southeast | Q4: 2883546.3 | S4: Home Goods | T4: 767715.33 | V4: 45717 | W4: 972561.45 | Y4: Providence RM-05 | Z4: 3.4172222
A5: Profit | B5: 3943052.1 | C5: Average Units Sold | D5: 126.43 | P5: Midwest | Q5: 2475171.6 | S5: Beauty | T5: 604999.69 | V5: 45748 | W5: 1029893.5 | Y5: Philadelphia RM-03 | Z5: 3.5522222
A6: Margin % | B6: 0.28393445 | C6: Sales per Employee | D6: 1814.1335 | P6: Northeast | Q6: 2456345.3 | S6: Sports | T6: 579316.91 | V6: 45778 | W6: 1122932.6 | Y6: Cleveland RM-13 | Z6: 3.5529167
A7: Avg Satisfaction | B7: 3.8484444 | C7: Best Satisfaction | D7: Seattle RM-16 (4.64) | S7: Grocery | T7: 78428.18 | V7: 45809 | W7: 1159230.2 | Y7: New Orleans RM-25 | Z7: 3.5691667
V8: 45839 | W8: 1199263.1 | Y8: Chicago RM-11 | Z8: 3.6016667
V9: 45870 | W9: 1186344.8 | Y9: Tampa RM-23 | Z9: 3.6377778
V10: 45901 | W10: 1076452.9 | Y10: Atlanta RM-09 | Z10: 3.67375
V11: 45931 | W11: 1134717.7 | Y11: Charlotte RM-10 | Z11: 3.6758333
V12: 45962 | W12: 1570487.9 | Y12: Denver RM-19 | Z12: 3.8070833
V13: 45992 | W13: 1763643 | Y13: Boston RM-02 | Z13: 3.8751389
Y14: Phoenix RM-18 | Z14: 3.8768056
Y15: Columbus RM-14 | Z15: 3.9016667
Y16: Dallas RM-06 | Z16: 3.9206944
Y17: Las Vegas RM-20 | Z17: 3.9325
Y18: Newark RM-01 | Z18: 3.9811111
Y19: Portland RM-17 | Z19: 3.9940278
Y20: Orlando RM-22 | Z20: 3.9961111
Y21: Indianapolis RM-15 | Z21: 4.06
Y22: Houston RM-08 | Z22: 4.0930556
Y23: Miami RM-21 | Z23: 4.1211111
Y24: Nashville RM-24 | Z24: 4.1840278
Y25: Austin RM-07 | Z25: 4.5463889
Y26: Seattle RM-16 | Z26: 4.6379167

Sheet Recommendations
A1: RetailMax Business Recommendations
A3: Recommendation | B3: Data Support | C3: Expected Business Impact | D3: Suggested Action | E3: Priority
A4: Shift marketing toward high-margin categories | B4: Beauty delivered the highest margin at 49.9%; Grocery generated only 7.8% margin. | C4: Improve gross margin without needing major sales volume growth. | D4: Bundle Beauty, Apparel, and Sports products; reduce blanket discounting on low-margin categories. | E4: High
A5: Fix low-satisfaction locations | B5: Detroit RM-12 had the lowest customer satisfaction at 3.25; Buffalo RM-04 was second lowest at 3.35. | C5: Improve retention, repeat visits, and service quality. | D5: Audit staffing, checkout wait times, inventory availability, and employee training in the lowest-rated stores. | E5: High
A6: Protect margins during seasonal spikes | B6: December produced the highest revenue ($1,763,643) but margin dropped to 22.9%. | C6: Preserve profit during periods where sales demand is naturally high. | D6: Use targeted promotions instead of full-store discounts; renegotiate seasonal vendor costs. | E6: Medium
A7: Scale winning practices from top stores | B7: Seattle RM-16 and Austin RM-07 generated the highest profits ($209,473 and $201,633). | C7: Replicate proven staffing, merchandising, and customer-service approaches. | D7: Interview top store managers and create a playbook for underperforming regions. | E7: Medium
